<?xml version="1.0" ?>
<!-- =================================================================================== -->
<!-- |    This document was autogenerated by xacro from victor.urdf.xacro              | -->
<!-- |    EDITING THIS FILE BY HAND IS NOT RECOMMENDED                                 | -->
<!-- =================================================================================== -->
<robot name="allegro">
  <material name="Black">
    <color rgba="0.0 0.0 0.0 1.0"/>
  </material>
  <material name="Blue">
    <color rgba="0.0 0.0 0.8 1.0"/>
  </material>
  <material name="Green">
    <color rgba="0.0 0.8 0.0 1.0"/>
  </material>
  <material name="Grey">
    <color rgba="0.4 0.4 0.4 1.0"/>
  </material>
  <material name="Orange">
    <color rgba="1.0 0.4235294117647059 0.0392156862745098 1.0"/>
  </material>
  <material name="Brown">
    <color rgba="0.8705882352941177 0.8117647058823529 0.7647058823529411 1.0"/>
  </material>
  <material name="Red">
    <color rgba="0.8 0.0 0.0 1.0"/>
  </material>
  <material name="White">
    <color rgba="1.0 1.0 1.0 1.0"/>
  </material>
  <material name="LightGrey">
    <color rgba="0.7 0.7 0.7 1"/>
  </material>
  <material name="DarkGray">
    <color rgba="0.2 0.2 0.2 1"/>
  </material>
  <material name="DarkDarkGray">
    <color rgba="0.1 0.1 0.1 1"/>
  </material>
  <!-- <link name="world">
    <inertial>
      <origin rpy="0 0 0" xyz="0 0 0.0"/>
      <mass value="100000.0"/>
      <inertia ixx="100000.0" ixy="0.0" ixz="0.0" iyy="100000.0" iyz="0.0" izz="100000.0"/>
    </inertial>
  </link>
  <joint name="world_joint" type="fixed">
    <parent link="world"/>
    <child link="victor_root"/>
    <origin rpy="0.0 0.0 0.0" xyz="0.0 0.0 0.0"/>
  </joint> -->
  <link name="victor_root"/>
  <joint name="victor_dummy_root_joint" type="fixed">
    <parent link="victor_root"/>
    <child link="victor_pedestal"/>
    <origin rpy="0 0 0" xyz="0 0 0"/>
    <axis xyz="0 0 1"/>
  </joint>
  <link name="victor_pedestal">
    <visual>
      <origin rpy="0 0 0" xyz="0 0 0.9245"/>
      <geometry>
        <mesh filename="mesh/baxter_pedestal/pedestal_visual.obj"/>
      </geometry>
      <material name="DarkGray"/>
    </visual>
    <collision>
      <origin rpy="0 0 0" xyz="0 0 0.9245"/>
      <geometry>
        <mesh filename="mesh/baxter_pedestal/pedestal_collision.obj"/>
      </geometry>
      <material name="DarkGray"/>
    </collision>
    <inertial>
      <origin rpy="0 0 0" xyz="0 0 0"/>
      <mass value="60.86397744"/>
      <inertia ixx="5.0635929" ixy="0.00103417" ixz="0.80199628" iyy="6.08689388" iyz="0.00105311" izz="4.96191932"/>
    </inertial>
  </link>
  <joint name="victor_base_plate_mount_joint" type="fixed">
    <parent link="victor_pedestal"/>
    <child link="victor_base_plate_mount"/>
    <origin rpy="0 0 0" xyz="0 0 0.863"/>
    <axis xyz="0 0 1"/>
  </joint>
  <link name="victor_base_plate_mount"/>
  <joint name="victor_base_plate_joint" type="fixed">
    <parent link="victor_base_plate_mount"/>
    <child link="victor_base_plate"/>
    <origin rpy="0 0 0" xyz="0 0 0"/>
    <axis xyz="0 0 1"/>
  </joint>
  <link name="victor_base_plate">
    <visual>
      <origin rpy="0 0 0" xyz="0 0 0"/>
      <geometry>
        <mesh filename="mesh/torso/torso_visual.obj"/>
      </geometry>
      <material name="LightGrey"/>
    </visual>
    <collision>
      <origin rpy="0 0 0" xyz="0 0 0.2"/>
      <geometry>
        <!--<mesh filename="mesh/torso_visual_model.obj"/>-->
        <cylinder length="0.7" radius="0.2"/>
      </geometry>
      <material name="LightGrey"/>
    </collision>
  </link>
  <joint name="victor_right_arm_mount_joint" type="fixed">
    <parent link="victor_base_plate"/>
    <child link="victor_right_arm_mount"/>
    <origin rpy="1.5707963268 0 0.785398163397448" xyz="-0.02 -0.1384885 0.385"/>
    <axis xyz="0 0 1"/>
  </joint>
  <link name="victor_right_arm_mount">
    <collision>
      <origin rpy="0 0 0" xyz="0 0 -0.013"/>
      <geometry>
        <!--<mesh filename="mesh/torso_visual_model.obj"/>-->
        <box size="0.31 0.31 0.032"/>
      </geometry>
      <material name="LightGrey"/>
    </collision>
  </link>

  <!--joint between {parent} and link_0-->
  <joint name="victor_right_arm_mount_victor_right_arm_joint" type="fixed">
    <origin rpy="0 0 0" xyz="0 0 0"/>
    <parent link="victor_right_arm_mount"/>
    <child link="victor_right_arm_link_0"/>
  </joint>
  <link name="victor_right_arm_link_0">
    <inertial>
      <origin rpy="0 0 0" xyz="-0.1 0 0.07"/>
      <mass value="5"/>
      <inertia ixx="0.05" ixy="0" ixz="0" iyy="0.06" iyz="0" izz="0.03"/>
    </inertial>
    <visual>
      <origin rpy="0 0 0" xyz="0 0 0"/>
      <geometry>
        <mesh filename="mesh/iiwa7/visual/link_0.obj"/>
      </geometry>
      <material name="Grey"/>
    </visual>
    <collision>
      <origin rpy="0 0 0" xyz="0 0 0"/>
      <geometry>
        <mesh filename="mesh/iiwa7/collision/link_0.obj"/>
      </geometry>
      <material name="Grey"/>
    </collision>
    <self_collision_checking>
      <origin rpy="0 0 0" xyz="0 0 0"/>
      <geometry>
        <capsule length="0.25" radius="0.15"/>
      </geometry>
    </self_collision_checking>
  </link>
  <!-- joint between link_0 and link_1 -->
  <joint name="victor_right_arm_joint_1" type="revolute">
    <parent link="victor_right_arm_link_0"/>
    <child link="victor_right_arm_link_1"/>
    <origin rpy="0 0 0" xyz="0 0 0.15"/>
    <axis xyz="0 0 1"/>
    <limit effort="300" lower="-2.9670597283903604" upper="2.9670597283903604" velocity="1.7453292519943295"/>
    <dynamics damping="0.5"/>
  </joint>
  <link name="victor_right_arm_link_1">
    <inertial>
      <origin rpy="0 0 0" xyz="0 -0.03 0.12"/>
      <mass value="3.4525"/>
      <inertia ixx="0.02183" ixy="0" ixz="0" iyy="0.007703" iyz="-0.003887" izz="0.02083"/>
    </inertial>
    <visual>
      <origin rpy="0 0 0" xyz="0 0 0.0075"/>
      <geometry>
        <mesh filename="mesh/iiwa7/visual/link_1.obj"/>
      </geometry>
      <material name="Orange"/>
    </visual>
    <collision>
      <origin rpy="0 0 0" xyz="0 0 0.0075"/>
      <geometry>
        <mesh filename="mesh/iiwa7/collision/link_1.obj"/>
      </geometry>
      <material name="Orange"/>
    </collision>
  </link>
  <joint name="victor_right_arm_joint_2" type="revolute">
    <parent link="victor_right_arm_link_1"/>
    <child link="victor_right_arm_link_2"/>
    <origin rpy="1.5707963267948966   0 3.141592653589793" xyz="0 0 0.19"/>
    <axis xyz="0 0 1"/>
    <limit effort="300" lower="-2.0943951023931953" upper="2.0943951023931953" velocity="1.7453292519943295"/>
    <dynamics damping="0.5"/>
  </joint>
  <link name="victor_right_arm_link_2">
    <inertial>
      <origin rpy="0 0 0" xyz="0.0003 0.059 0.042"/>
      <mass value="3.4821"/>
      <inertia ixx="0.02076" ixy="0" ixz="-0.003626" iyy="0.02179" iyz="0" izz="0.00779"/>
    </inertial>
    <visual>
      <origin rpy="0 0 0" xyz="0 0 0"/>
      <geometry>
        <mesh filename="mesh/iiwa7/visual/link_2.obj"/>
      </geometry>
      <material name="Orange"/>
    </visual>
    <collision>
      <origin rpy="0 0 0" xyz="0 0 0"/>
      <geometry>
        <mesh filename="mesh/iiwa7/collision/link_2.obj"/>
      </geometry>
      <material name="Orange"/>
    </collision>
  </link>
  <joint name="victor_right_arm_joint_3" type="revolute">
    <parent link="victor_right_arm_link_2"/>
    <child link="victor_right_arm_link_3"/>
    <origin rpy="1.5707963267948966 0 3.141592653589793" xyz="0 0.21 0"/>
    <axis xyz="0 0 1"/>
    <limit effort="300" lower="-2.9670597283903604" upper="2.9670597283903604" velocity="1.7453292519943295"/>
    <dynamics damping="0.5"/>
  </joint>
  <link name="victor_right_arm_link_3">
    <inertial>
      <origin rpy="0 0 0" xyz="0 0.03 0.13"/>
      <mass value="4.05623"/>
      <inertia ixx="0.03204" ixy="0" ixz="0" iyy="0.00972" iyz="0.006227" izz="0.03042"/>
    </inertial>
    <visual>
      <origin rpy="0 0 0" xyz="0 0 -0.026"/>
      <geometry>
        <mesh filename="mesh/iiwa7/visual/link_3.obj"/>
      </geometry>
      <material name="Orange"/>
    </visual>
    <collision>
      <origin rpy="0 0 0" xyz="0 0 -0.026"/>
      <geometry>
        <mesh filename="mesh/iiwa7/collision/link_3.obj"/>
      </geometry>
      <material name="Orange"/>
    </collision>
  </link>
  <joint name="victor_right_arm_joint_4" type="revolute">
    <parent link="victor_right_arm_link_3"/>
    <child link="victor_right_arm_link_4"/>
    <origin rpy="1.5707963267948966 0 0" xyz="0 0 0.19"/>
    <axis xyz="0 0 1"/>
    <limit effort="300" lower="-2.0943951023931953" upper="2.0943951023931953" velocity="2.2689280275926285"/>
    <dynamics damping="0.5"/>
  </joint>
  <link name="victor_right_arm_link_4">
    <inertial>
      <origin rpy="0 0 0" xyz="0 0.067 0.034"/>
      <mass value="3.4822"/>
      <inertia ixx="0.02178" ixy="0" ixz="0" iyy="0.02075" iyz="-0.003625" izz="0.007785"/>
    </inertial>
    <visual>
      <origin rpy="0 0 0" xyz="0 0 0"/>
      <geometry>
        <mesh filename="mesh/iiwa7/visual/link_4.obj"/>
      </geometry>
      <material name="Orange"/>
    </visual>
    <collision>
      <origin rpy="0 0 0" xyz="0 0 0"/>
      <geometry>
        <mesh filename="mesh/iiwa7/collision/link_4.obj"/>
      </geometry>
      <material name="Orange"/>
    </collision>
  </link>
  <joint name="victor_right_arm_joint_5" type="revolute">
    <parent link="victor_right_arm_link_4"/>
    <child link="victor_right_arm_link_5"/>
    <origin rpy="-1.5707963267948966 3.141592653589793 0" xyz="0 0.21 0"/>
    <axis xyz="0 0 1"/>
    <limit effort="300" lower="-2.9670597283903604" upper="2.9670597283903604" velocity="2.443460952792061"/>
    <dynamics damping="0.5"/>
  </joint>
  <link name="victor_right_arm_link_5">
    <inertial>
      <origin rpy="0 0 0" xyz="0.0001 0.021 0.076"/>
      <mass value="2.1633"/>
      <inertia ixx="0.01287" ixy="0" ixz="0" iyy="0.005708" iyz="-0.003946" izz="0.01112"/>
    </inertial>
    <visual>
      <origin rpy="0 0 0" xyz="0 0 -0.026"/>
      <geometry>
        <mesh filename="mesh/iiwa7/visual/link_5.obj"/>
      </geometry>
      <material name="Orange"/>
    </visual>
    <collision>
      <origin rpy="0 0 0" xyz="0 0 -0.026"/>
      <geometry>
        <mesh filename="mesh/iiwa7/collision/link_5.obj"/>
      </geometry>
      <material name="Orange"/>
    </collision>
  </link>
  <joint name="victor_right_arm_joint_6" type="revolute">
    <parent link="victor_right_arm_link_5"/>
    <child link="victor_right_arm_link_6"/>
    <origin rpy="1.5707963267948966 0 0" xyz="0 0.06070 0.19"/>
    <axis xyz="0 0 1"/>
    <limit effort="300" lower="-2.0943951023931953" upper="2.0943951023931953" velocity="3.141592653589793"/>
    <dynamics damping="0.5"/>
  </joint>
  <link name="victor_right_arm_link_6">
    <inertial>
      <origin rpy="0 0 0" xyz="0 0.0006 0.0004"/>
      <mass value="2.3466"/>
      <inertia ixx="0.006509" ixy="0" ixz="0" iyy="0.006259" iyz="0.00031891" izz="0.004527"/>
    </inertial>
    <visual>
      <origin rpy="0 0 0" xyz="0 0 0"/>
      <geometry>
        <mesh filename="mesh/iiwa7/visual/link_6.obj"/>
      </geometry>
      <material name="Orange"/>
    </visual>
    <collision>
      <origin rpy="0 0 0" xyz="0 0 0"/>
      <geometry>
        <mesh filename="mesh/iiwa7/collision/link_6.obj"/>
      </geometry>
      <material name="Orange"/>
    </collision>
  </link>
  <joint name="victor_right_arm_joint_7" type="revolute">
    <parent link="victor_right_arm_link_6"/>
    <child link="victor_right_arm_link_7"/>
    <origin rpy="-1.5707963267948966 3.141592653589793 0" xyz="0 0.081 0.06070"/>
    <axis xyz="0 0 1"/>
    <limit effort="300" lower="-3.0543261909900763" upper="3.0543261909900763" velocity="3.141592653589793"/>
    <dynamics damping="0.5"/>
  </joint>
  <link name="victor_right_arm_link_7">
    <inertial>
      <origin rpy="0 0 0" xyz="0 0 0.02"/>
      <mass value="3.129"/>
      <inertia ixx="0.01464" ixy="0.0005912" ixz="0" iyy="0.01465" iyz="0" izz="0.002872"/>
    </inertial>
    <visual>
      <origin rpy="0 0 0" xyz="0 0 -0.0005"/>
      <geometry>
        <mesh filename="mesh/iiwa7/visual/link_7_electric.obj"/>
      </geometry>
      <material name="Grey"/>
    </visual>
    <collision>
      <origin rpy="0 0 0" xyz="0 0 -0.0005"/>
      <geometry>
        <mesh filename="mesh/iiwa7/collision/link_7_electric.obj"/>
      </geometry>
      <material name="Grey"/>
    </collision>
  </link>
  <joint name="victor_right_arm_joint_flange" type="fixed">
    <parent link="victor_right_arm_link_7"/>
    <child link="victor_right_arm_flange"/>
    <origin rpy="0 0 0" xyz="0 0 0.045"/>
  </joint>
  <link name="victor_right_arm_flange">
        </link>
  <!-- Our usage above has been tweaked to match Kuka's internal usage, so identity transform -->
  <joint name="victor_right_arm_flange_kuka_joint" type="fixed">
    <parent link="victor_right_arm_flange"/>
    <child link="victor_right_arm_flange_kuka"/>
    <origin rpy="0 0 0" xyz="0 0 0"/>
  </joint>
  <link name="victor_right_arm_flange_kuka">
        </link>



  <!-- Link0 -->
  <gazebo reference="victor_right_arm_link_0">
    <kinematic>0</kinematic>
    <mu1>0.2</mu1>
    <mu2>0.2</mu2>
  </gazebo>
  <!-- Link1 -->
  <gazebo reference="victor_right_arm_link_1">
    <kinematic>0</kinematic>
    <mu1>0.2</mu1>
    <mu2>0.2</mu2>
  </gazebo>
  <!-- Link2 -->
  <gazebo reference="victor_right_arm_link_2">
    <kinematic>0</kinematic>
    <mu1>0.2</mu1>
    <mu2>0.2</mu2>
  </gazebo>
  <!-- Link3 -->
  <gazebo reference="victor_right_arm_link_3">
    <kinematic>0</kinematic>
    <mu1>0.2</mu1>
    <mu2>0.2</mu2>
  </gazebo>
  <!-- Link4 -->
  <gazebo reference="victor_right_arm_link_4">
    <kinematic>0</kinematic>
    <mu1>0.2</mu1>
    <mu2>0.2</mu2>
  </gazebo>
  <!-- Link5 -->
  <gazebo reference="victor_right_arm_link_5">
    <kinematic>0</kinematic>
    <mu1>0.2</mu1>
    <mu2>0.2</mu2>
  </gazebo>
  <!-- Link6 -->
  <gazebo reference="victor_right_arm_link_6">
    <kinematic>0</kinematic>
    <mu1>0.2</mu1>
    <mu2>0.2</mu2>
  </gazebo>
  <!-- Link7 -->
  <gazebo reference="victor_right_arm_link_7">
    <kinematic>0</kinematic>
    <mu1>0.2</mu1>
    <mu2>0.2</mu2>
  </gazebo>
  <transmission name="victor_right_arm_tran_1">
    <type>transmission_interface/SimpleTransmission</type>
    <joint name="victor_right_arm_joint_1">
      <hardwareInterface>hardware_interface/PositionJointInterface</hardwareInterface>
    </joint>
    <actuator name="victor_right_arm_motor_1">
      <mechanicalReduction>1</mechanicalReduction>
    </actuator>
  </transmission>
  <transmission name="victor_right_arm_tran_2">
    <type>transmission_interface/SimpleTransmission</type>
    <joint name="victor_right_arm_joint_2">
      <hardwareInterface>hardware_interface/PositionJointInterface</hardwareInterface>
    </joint>
    <actuator name="victor_right_arm_motor_2">
      <mechanicalReduction>1</mechanicalReduction>
    </actuator>
  </transmission>
  <transmission name="victor_right_arm_tran_3">
    <type>transmission_interface/SimpleTransmission</type>
    <joint name="victor_right_arm_joint_3">
      <hardwareInterface>hardware_interface/PositionJointInterface</hardwareInterface>
    </joint>
    <actuator name="victor_right_arm_motor_3">
      <mechanicalReduction>1</mechanicalReduction>
    </actuator>
  </transmission>
  <transmission name="victor_right_arm_tran_4">
    <type>transmission_interface/SimpleTransmission</type>
    <joint name="victor_right_arm_joint_4">
      <hardwareInterface>hardware_interface/PositionJointInterface</hardwareInterface>
    </joint>
    <actuator name="victor_right_arm_motor_4">
      <mechanicalReduction>1</mechanicalReduction>
    </actuator>
  </transmission>
  <transmission name="victor_right_arm_tran_5">
    <type>transmission_interface/SimpleTransmission</type>
    <joint name="victor_right_arm_joint_5">
      <hardwareInterface>hardware_interface/PositionJointInterface</hardwareInterface>
    </joint>
    <actuator name="victor_right_arm_motor_5">
      <mechanicalReduction>1</mechanicalReduction>
    </actuator>
  </transmission>
  <transmission name="victor_right_arm_tran_6">
    <type>transmission_interface/SimpleTransmission</type>
    <joint name="victor_right_arm_joint_6">
      <hardwareInterface>hardware_interface/PositionJointInterface</hardwareInterface>
    </joint>
    <actuator name="victor_right_arm_motor_6">
      <mechanicalReduction>1</mechanicalReduction>
    </actuator>
  </transmission>
  <transmission name="victor_right_arm_tran_7">
    <type>transmission_interface/SimpleTransmission</type>
    <joint name="victor_right_arm_joint_7">
      <hardwareInterface>hardware_interface/PositionJointInterface</hardwareInterface>
    </joint>
    <actuator name="victor_right_arm_motor_7">
      <mechanicalReduction>1</mechanicalReduction>
    </actuator>
  </transmission>
  <joint name="victor_joint_right_arm_world_frame_kuka" type="fixed">
    <parent link="victor_right_arm_mount"/>
    <child link="victor_right_arm_world_frame_kuka"/>
    <origin rpy="-1.57079632679 0 0" xyz="0 0 0"/>
  </joint>
  <link name="victor_right_arm_world_frame_kuka">
    </link>
  <joint name="victor_right_arm_joint_ee" type="fixed">
    <parent link="victor_right_arm_link_7"/>
    <child link="victor_right_arm_link_ee"/>
    <origin rpy="0 0 0" xyz="0 0 0.04"/>
  </joint>
  <link name="victor_right_arm_link_ee">
    <inertial>
      <origin rpy="0 0 0" xyz="0 0 0.0"/>
      <mass value="0.0"/>
      <inertia ixx="0.0" ixy="0.0" ixz="0.0" iyy="0.0" iyz="0.0" izz="0.0"/>
    </inertial>
  </link>
  <joint name="victor_allegro" type="fixed">
    <parent link="victor_right_arm_link_ee"/>
    <child link="allegro_hand_base_link"/>
    <origin rpy="0 0 0" xyz="0.0 0.0 0.1"/>
  </joint>

  <link name="allegro_hand_base_link">
    <visual>
      <geometry>
        <mesh filename="mesh/allegro/base_ns.stl"/>
      </geometry>
      <origin rpy="0 0 0" xyz="0 0 0 "/>
      <material name="black">
        <color rgba="0.0 1.0 1.0 1"/>
      </material>
    </visual>
    <collision>
      <!-- <origin rpy="0 0 0" xyz="-0.009300 0 -0.0475"/> -->
      <geometry>
        <mesh filename="mesh/allegro/base_ns.stl"/>
        <!-- <box size="0.0408 0.1130 0.095"/> -->
      </geometry>
    </collision>
    <inertial>
      <mass value="0.4154"/>
      <origin rpy="0 0 0" xyz="0 0 0"/>
      <inertia ixx="1.87e-03" ixy="0.0" ixz="8.31e-06" iyy="1.13e-03" iyz="0.0" izz="1.11e-03"/>
    </inertial>
  </link>
  <link name="allegro_hand_hitosashi_finger_finger_link_0">
    <visual>
      <geometry>
        <mesh filename="mesh/allegro/link_0.0_ext.STL"/>
      </geometry>
      <material name="grey"/>
    </visual>
    <collision>
      <geometry>
        <box size="0.0196 0.0275 0.0164"/>
      </geometry>
      <origin rpy="0 0 0" xyz="0 0 0.011200000000000002"/>
    </collision>
    <inertial>
      <mass value="0.0127"/>
      <origin rpy="0 0 0" xyz="0 0 0"/>
      <inertia ixx="1.138e-06" ixy="1.27e-10" ixz="4.83e-09" iyy="6.683e-07" iyz="0.0" izz="0.0010001160000000001"/>
    </inertial>
  </link>
  <joint name="allegro_hand_hitosashi_finger_finger_joint_0" type="revolute">
    <axis xyz="0 0 1"/>
    <limit effort="10" lower="-0.47" upper="0.47" velocity="0.5"/>
    <parent link="allegro_hand_base_link"/>
    <child link="allegro_hand_hitosashi_finger_finger_link_0"/>
    <origin rpy="-0.08726646259971647 0 0" xyz="0 0.0435 -0.001542"/>
  </joint>
  <link name="allegro_hand_hitosashi_finger_finger_link_1">
    <visual>
      <geometry>
        <mesh filename="mesh/allegro/link_1.0.stl"/>
      </geometry>
      <material name="black"/>
    </visual>
    <collision>
      <geometry>
        <!-- <mesh filename="mesh/allegro/link_1.0.stl"/> -->
        <box size="0.0196 0.0275 0.0254"/>
      </geometry>
      <origin rpy="0 0 0" xyz="0 0 0.0232"/>
    </collision>
    <inertial>
      <mass value="0.809"/>
      <origin rpy="0 0 0" xyz="0 0 0"/>
      <inertia ixx="7.95654166667e-05" ixy="1.7199e-05" ixz="8.75875e-06" iyy="0.0010247088833333" iyz="2.413125e-05" izz="7.95654166667e-05"/>
    </inertial>
  </link>
  <joint name="allegro_hand_hitosashi_finger_finger_joint_1" type="revolute">
    <limit effort="10" lower="-0.19599999999999998" upper="1.6099999999999999" velocity="0.5"/>
    <axis xyz="0 1 0"/>
    <parent link="allegro_hand_hitosashi_finger_finger_link_0"/>
    <child link="allegro_hand_hitosashi_finger_finger_link_1"/>
    <origin xyz="0 0 0.0204"/>
    <!-- New height on fingers -->
  </joint>
  <link name="allegro_hand_hitosashi_finger_finger_link_2">
    <visual>
      <geometry>
        <mesh filename="mesh/allegro/link_2.0.stl"/>
        <!--   <mesh filename="mesh_nvidia/primary_proximal.obj"/> -->
      </geometry>
      <material name="black"/>
    </visual>
    <collision>
      <geometry>
      <!-- <mesh filename="mesh/allegro/link_2.0.stl"/> -->
        <!-- <box size="0.0196 0.0275 0.054"/> -->
        <box size="0.0196 0.0275 0.03"/>

      </geometry>
      <origin rpy="0 0 0" xyz="0 0 0.007"/>
    </collision>
    <!--covers are always with sensors-->
    <inertial>
      <mass value="0.0447"/>
      <origin rpy="0 0 0" xyz="0 0 0"/>
      <inertia ixx="2.63979183333e-05" ixy="6.67968e-06" ixz="4.783625e-06" iyy="0.0010134948516667" iyz="9.372e-06" izz="2.63979183333e-05"/>
    </inertial>
  </link>
  <joint name="allegro_hand_hitosashi_finger_finger_joint_2" type="revolute">
    <axis xyz="0 1 0"/>
    <limit effort="10" lower="-0.17400000000000002" upper="1.7089999999999999" velocity="0.5"/>
    <parent link="allegro_hand_hitosashi_finger_finger_link_1"/>
    <child link="allegro_hand_hitosashi_finger_finger_link_2"/>
    <origin xyz="0 0 0.054"/>
  </joint>
  <link name="allegro_hand_hitosashi_finger_finger_link_3">
    <visual>
      <geometry>
        <mesh filename="mesh/allegro/link_3.0.STL"/>
      </geometry>
      <material name="black"/>
    </visual>
    <collision>
      <geometry>
        <box size="0.0196 0.0275 0.026399999999999996"/>
        <!-- <mesh filename="mesh/allegro/link_3.0.STL"/> -->
      </geometry>
      <origin rpy="0 0 0" xyz="0 0 0.013199999999999998"/>
    </collision>
    <inertial>
      <mass value="0.0404"/>
      <origin rpy="0 0 0" xyz="0 0 0"/>
      <inertia ixx="4.701248e-06" ixy="1.255968e-06" ixz="1.2936e-06" iyy="0.001003649312" iyz="1.7622e-06" izz="4.701248e-06"/>
    </inertial>
  </link>
  <joint name="allegro_hand_hitosashi_finger_finger_joint_3" type="revolute">
    <axis xyz="0 1 0"/>
    <limit effort="10" lower="-0.227" upper="1.6179999999999999" velocity="0.5"/>
    <parent link="allegro_hand_hitosashi_finger_finger_link_2"/>
    <child link="allegro_hand_hitosashi_finger_finger_link_3"/>
    <origin xyz="0 0.0 0.0384"/>
  </joint>
  <joint name="allegro_hand_hitosashi_finger_finger_0_aftc_fixed" type="fixed">
    <origin rpy="1.5707963267948966 0.0 1.5707963267948966" xyz="-0.013 0.0 0.016"/>
    <parent link="allegro_hand_hitosashi_finger_finger_link_3"/>
    <child link="allegro_hand_hitosashi_finger_finger_0_aftc_base_link"/>
  </joint>
  <link name="allegro_hand_hitosashi_finger_finger_0_aftc_base_link">
    <collision>
      <origin rpy="0 0 0" xyz="0 0 0"/>
      <geometry>
        <mesh filename="mesh/ft_c.stl"/>
      </geometry>
    </collision>
    <visual>
      <origin rpy="0 0 0" xyz="0 0 0"/>
      <geometry>
        <mesh filename="mesh/ft_c.stl"/>
      </geometry>
      <material name="black"/>
    </visual>
    <inertial>
      <!-- <friction value="1.0"/> -->
      <mass value="0.0404"/>
      <origin rpy="0 0 0" xyz="0 0 0"/>
    </inertial>
  </link>
  <joint name="allegro_hand_hitosashi_tip_fixed" type="fixed">
    <origin rpy="0 0.0 0" xyz="0 0.03 0"/>
    <parent link="allegro_hand_hitosashi_finger_finger_0_aftc_base_link"/>
    <child link="hitosashi_ee"/>
  </joint>
  <link name="hitosashi_ee">
    <inertial>
        <mass value="0.0001"/>
        <origin rpy="0 0 0" xyz="0 0 0"/>
        <inertia ixx="1e-07" ixy="0.0" ixz="0.0" iyy="1e-07" iyz="0.0" izz="1e-07"/>
    </inertial>
  </link>
  <link name="allegro_hand_naka_finger_finger_link_4">
    <visual>
      <geometry>
        <mesh filename="mesh/allegro/link_0.0_ext.STL"/>
      </geometry>
      <material name="grey"/>
    </visual>
    <collision>
      <geometry>
        <box size="0.0196 0.0275 0.0164"/>
      </geometry>
      <origin rpy="0 0 0" xyz="0 0 0.011200000000000002"/>
    </collision>
    <inertial>
      <mass value="0.0127"/>
      <origin rpy="0 0 0" xyz="0 0 0"/>
      <inertia ixx="1.138e-06" ixy="1.27e-10" ixz="4.83e-09" iyy="6.683e-07" iyz="0.0" izz="0.0010001160000000001"/>
    </inertial>
  </link>
  <joint name="allegro_hand_naka_finger_finger_joint_4" type="revolute">
    <axis xyz="0 0 1"/>
    <limit effort="10" lower="-0.47" upper="0.47" velocity="0.5"/>
    <parent link="allegro_hand_base_link"/>
    <child link="allegro_hand_naka_finger_finger_link_4"/>
    <origin rpy="0.0 0 0" xyz="0 0 0.0007"/>
  </joint>
  <link name="allegro_hand_naka_finger_finger_link_5">
    <visual>
      <geometry>
        <mesh filename="mesh/allegro/link_1.0.stl"/>
      </geometry>
      <material name="black"/>
    </visual>
    <collision>
      <geometry>
        <!-- <mesh filename="mesh/allegro/link_1.0.stl"/> -->
        <box size="0.0196 0.0275 0.0164"/>
      </geometry>
      <origin rpy="0 0 0" xyz="0 0 0.0082"/>
    </collision>
    <inertial>
      <mass value="0.809"/>
      <origin rpy="0 0 0" xyz="0 0 0"/>
      <inertia ixx="7.95654166667e-05" ixy="1.7199e-05" ixz="8.75875e-06" iyy="0.0010247088833333" iyz="2.413125e-05" izz="7.95654166667e-05"/>
    </inertial>
  </link>
  <joint name="allegro_hand_naka_finger_finger_joint_5" type="revolute">
    <limit effort="10" lower="-0.19599999999999998" upper="1.6099999999999999" velocity="0.5"/>
    <axis xyz="0 1 0"/>
    <parent link="allegro_hand_naka_finger_finger_link_4"/>
    <child link="allegro_hand_naka_finger_finger_link_5"/>
    <origin xyz="0 0 0.0204"/>
    <!-- New height on fingers -->
  </joint>
  <link name="allegro_hand_naka_finger_finger_link_6">
    <visual>
      <geometry>
        <mesh filename="mesh/allegro/link_2.0.stl"/>
      </geometry>
      <material name="black"/>
    </visual>
    <collision>
      <geometry>
        <!-- <box size="0.0196 0.0275 0.04"/> -->
        <box size="0.0196 0.0275 0.02"/>
      </geometry>
      <origin rpy="0 0 0" xyz="0 0 0.027"/>
    </collision>
    <!--covers are always with sensors-->
    <inertial>
      <mass value="0.0447"/>
      <origin rpy="0 0 0" xyz="0 0 0"/>
      <inertia ixx="2.63979183333e-05" ixy="6.67968e-06" ixz="4.783625e-06" iyy="0.0010134948516667" iyz="9.372e-06" izz="2.63979183333e-05"/>
    </inertial>
  </link>
  <joint name="allegro_hand_naka_finger_finger_joint_6" type="revolute">
    <axis xyz="0 1 0"/>
    <limit effort="10" lower="-0.17400000000000002" upper="1.7089999999999999" velocity="0.5"/>
    <parent link="allegro_hand_naka_finger_finger_link_5"/>
    <child link="allegro_hand_naka_finger_finger_link_6"/>
    <origin xyz="0 0 0.054"/>
  </joint>
  <link name="allegro_hand_naka_finger_finger_link_7">
    <visual>
      <geometry>
        <mesh filename="mesh/allegro/link_3.0.STL"/>
      </geometry>
      <material name="black"/>
    </visual>
    <collision>
      <geometry>
        <!-- <box size="0.0196 0.0275 0.026399999999999996"/> -->
        <box size="0.0196 0.0275 0.02"/>
      </geometry>
      <origin rpy="0 0 0" xyz="0 0 0.013199999999999998"/>
    </collision>
    <inertial>
      <mass value="0.0404"/>
      <origin rpy="0 0 0" xyz="0 0 0"/>
      <inertia ixx="4.701248e-06" ixy="1.255968e-06" ixz="1.2936e-06" iyy="0.001003649312" iyz="1.7622e-06" izz="4.701248e-06"/>
    </inertial>
  </link>
  <joint name="allegro_hand_naka_finger_finger_joint_7" type="revolute">
    <axis xyz="0 1 0"/>
    <limit effort="10" lower="-0.227" upper="1.6179999999999999" velocity="0.5"/>
    <parent link="allegro_hand_naka_finger_finger_link_6"/>
    <child link="allegro_hand_naka_finger_finger_link_7"/>
    <origin xyz="0 0.0 0.0384"/>
  </joint>
  <joint name="allegro_hand_naka_finger_finger_1_aftc_fixed" type="fixed">
    <origin rpy="1.5707963267948966 0.0 1.5707963267948966" xyz="-0.013 0.0 0.016"/>
    <parent link="allegro_hand_naka_finger_finger_link_7"/>
    <child link="allegro_hand_naka_finger_finger_1_aftc_base_link"/>
  </joint>
  <link name="allegro_hand_naka_finger_finger_1_aftc_base_link">
    <collision>
      <origin rpy="0 0 0" xyz="0 0 0"/>
      <geometry>
        <mesh filename="mesh/ft_c.stl"/>
      </geometry>
    </collision>
    <visual>
      <origin rpy="0 0 0" xyz="0 0 0"/>
      <geometry>
        <mesh filename="mesh/ft_c.stl"/>
      </geometry>
      <material name="black"/>
    </visual>
    <inertial>
      <!-- <friction value="1.0"/> -->
      <mass value="0.0404"/>
      <origin rpy="0 0 0" xyz="0 0 0"/>
    </inertial>
  </link>
  <joint name="allegro_hand_naka_tip_fixed" type="fixed">
    <origin rpy="0 0.0 0" xyz="0 0.03 0"/>
    <parent link="allegro_hand_naka_finger_finger_1_aftc_base_link"/>
    <child link="naka_ee"/>
  </joint>
  <link name="naka_ee">
    <inertial>
        <mass value="0.0001"/>
        <origin rpy="0 0 0" xyz="0 0 0"/>
        <inertia ixx="1e-07" ixy="0.0" ixz="0.0" iyy="1e-07" iyz="0.0" izz="1e-07"/>
    </inertial>
  </link>
  <link name="allegro_hand_kusuri_finger_finger_link_8">
    <visual>
      <geometry>
        <mesh filename="mesh/allegro/link_0.0_ext.STL"/>
      </geometry>
      <material name="grey"/>
    </visual>
    <collision>
      <geometry>
        <box size="0.0196 0.0275 0.0164"/>
      </geometry>
      <origin rpy="0 0 0" xyz="0 0 0.011200000000000002"/>
    </collision>
    <inertial>
      <mass value="0.0127"/>
      <origin rpy="0 0 0" xyz="0 0 0"/>
      <inertia ixx="1.138e-06" ixy="1.27e-10" ixz="4.83e-09" iyy="6.683e-07" iyz="0.0" izz="0.0010001160000000001"/>
    </inertial>
  </link>
  <joint name="allegro_hand_kusuri_finger_finger_joint_8" type="revolute">
    <axis xyz="0 0 1"/>
    <limit effort="10" lower="-0.47" upper="0.47" velocity="0.5"/>
    <parent link="allegro_hand_base_link"/>
    <child link="allegro_hand_kusuri_finger_finger_link_8"/>
    <origin rpy="0.08726646259971647 0 0" xyz="0 -0.0435 -0.001542"/>
  </joint>
  <link name="allegro_hand_kusuri_finger_finger_link_9">
    <visual>
      <geometry>
        <mesh filename="mesh/allegro/link_1.0.stl"/>
      </geometry>
      <material name="black"/>
    </visual>
    <collision>
      <geometry>
        <mesh filename="mesh/allegro/link_1.0.stl"/>
        <!-- <box size="0.0196 0.0275 0.0164"/> -->
      </geometry>
      <!-- <origin rpy="0 0 0" xyz="0 0 0.0082"/> -->
    </collision>
    <inertial>
      <mass value="0.809"/>
      <origin rpy="0 0 0" xyz="0 0 0"/>
      <inertia ixx="7.95654166667e-05" ixy="1.7199e-05" ixz="8.75875e-06" iyy="0.0010247088833333" iyz="2.413125e-05" izz="7.95654166667e-05"/>
    </inertial>
  </link>
  <joint name="allegro_hand_kusuri_finger_finger_joint_9" type="revolute">
    <limit effort="10" lower="-0.19599999999999998" upper="1.6099999999999999" velocity="0.5"/>
    <axis xyz="0 1 0"/>
    <parent link="allegro_hand_kusuri_finger_finger_link_8"/>
    <child link="allegro_hand_kusuri_finger_finger_link_9"/>
    <origin xyz="0 0 0.0204"/>
    <!-- New height on fingers -->
  </joint>
  <link name="allegro_hand_kusuri_finger_finger_link_10">
    <visual>
      <geometry>
        <mesh filename="mesh/allegro/link_2.0.stl"/>
      </geometry>
      <material name="black"/>
    </visual>
    <collision>
      <geometry>
        <box size="0.0196 0.0275 0.04"/>
      </geometry>
      <origin rpy="0 0 0" xyz="0 0 0.027"/>
    </collision>
    <!--covers are always with sensors-->
    <inertial>
      <mass value="0.0447"/>
      <origin rpy="0 0 0" xyz="0 0 0"/>
      <inertia ixx="2.63979183333e-05" ixy="6.67968e-06" ixz="4.783625e-06" iyy="0.0010134948516667" iyz="9.372e-06" izz="2.63979183333e-05"/>
    </inertial>
  </link>
  <joint name="allegro_hand_kusuri_finger_finger_joint_10" type="revolute">
    <axis xyz="0 1 0"/>
    <limit effort="10" lower="-0.17400000000000002" upper="1.7089999999999999" velocity="0.5"/>
    <parent link="allegro_hand_kusuri_finger_finger_link_9"/>
    <child link="allegro_hand_kusuri_finger_finger_link_10"/>
    <origin xyz="0 0 0.054"/>
  </joint>
  <link name="allegro_hand_kusuri_finger_finger_link_11">
    <visual>
      <geometry>
        <mesh filename="mesh/allegro/link_3.0.STL"/>
      </geometry>
      <material name="black"/>
    </visual>
    <collision>
      <geometry>
        <box size="0.0196 0.0275 0.026399999999999996"/>
      </geometry>
      <origin rpy="0 0 0" xyz="0 0 0.013199999999999998"/>
    </collision>
    <inertial>
      <mass value="0.0404"/>
      <origin rpy="0 0 0" xyz="0 0 0"/>
      <inertia ixx="4.701248e-06" ixy="1.255968e-06" ixz="1.2936e-06" iyy="0.001003649312" iyz="1.7622e-06" izz="4.701248e-06"/>
    </inertial>
  </link>
  <joint name="allegro_hand_kusuri_finger_finger_joint_11" type="revolute">
    <axis xyz="0 1 0"/>
    <limit effort="10" lower="-0.227" upper="1.6179999999999999" velocity="0.5"/>
    <parent link="allegro_hand_kusuri_finger_finger_link_10"/>
    <child link="allegro_hand_kusuri_finger_finger_link_11"/>
    <origin xyz="0 0.0 0.0384"/>
  </joint>
  <joint name="allegro_hand_kusuri_finger_finger_2_aftc_fixed" type="fixed">
    <origin rpy="1.5707963267948966 0.0 1.5707963267948966" xyz="-0.013 0.0 0.016"/>
    <parent link="allegro_hand_kusuri_finger_finger_link_11"/>
    <child link="allegro_hand_kusuri_finger_finger_2_aftc_base_link"/>
  </joint>
  <link name="allegro_hand_kusuri_finger_finger_2_aftc_base_link">
    <collision>
      <origin rpy="0 0 0" xyz="0 0 0"/>
      <geometry>
        <mesh filename="mesh/ft_c.stl"/>
      </geometry>
    </collision>
    <visual>
      <origin rpy="0 0 0" xyz="0 0 0"/>
      <geometry>
        <mesh filename="mesh/ft_c.stl"/>
      </geometry>
      <material name="black"/>
    </visual>
    <inertial>
      <!-- <friction value="1.0"/> -->
      <mass value="0.0404"/>
      <origin rpy="0 0 0" xyz="0 0 0"/>
    </inertial>
  </link>
  <joint name="allegro_hand_kusuri_tip_fixed" type="fixed">
    <origin rpy="0 0.0 0" xyz="0 0.03 0"/>
    <parent link="allegro_hand_kusuri_finger_finger_2_aftc_base_link"/>
    <child link="kusuri_ee"/>
  </joint>
  <link name="kusuri_ee">
    <inertial>
        <mass value="0.0001"/>
        <origin rpy="0 0 0" xyz="0 0 0"/>
        <inertia ixx="1e-07" ixy="0.0" ixz="0.0" iyy="1e-07" iyz="0.0" izz="1e-07"/>
    </inertial>
  </link>
  <link name="allegro_hand_oya_finger_link_12">
    <visual>
      <geometry>
        <mesh filename="mesh/allegro/link_12.0_right.STL"/>
      </geometry>
      <material name="grey"/>
    </visual>
    <collision>
      <geometry>
        <box size="0.00358 0.0034 0.00455"/>
      </geometry>
      <origin rpy="0 0 0" xyz="-0.0179 0.009 0.0145"/>
    </collision>
    <inertial>
      <mass value="0.0176"/>
      <origin rpy="0 0 0" xyz="0 0 0"/>
      <inertia ixx="0.0010189273333333" ixy="7.16716e-06" ixz="5.35568e-06" iyy="1.43008213333e-05" iyz="6.8068e-06" izz="1.89273333333e-05"/>
    </inertial>
  </link>
  <joint name="allegro_hand_oya_finger_joint_12" type="revolute">
    <axis xyz="-1 0 0"/>
    <limit effort="10" lower="0.263" upper="1.5" velocity="0.5"/>
    <parent link="allegro_hand_base_link"/>
    <child link="allegro_hand_oya_finger_link_12"/>
    <origin rpy="0 -1.6580627893946132 -1.5707963267948966" xyz="-0.0182 0.019333 -0.045987"/>
  </joint>
  <link name="allegro_hand_oya_finger_link_13">
    <visual>
      <geometry>
        <mesh filename="mesh/allegro/link_13.0.STL"/>
      </geometry>
      <material name="grey"/>
    </visual>
    <collision>
      <geometry>
        <box size="0.0196 0.0275 0.01"/>
      </geometry>
      <origin rpy="0 0 0" xyz="0 0 0.00885"/>
    </collision>
    <inertial>
      <mass value="0.0127"/>
      <origin rpy="0 0 0" xyz="0 0 0"/>
      <inertia ixx="4.24250866667e-06" ixy="1.032087e-06" ixz="1.603525e-06" iyy="4.52362633333e-06" iyz="1.44808125e-06" izz="0.00100424250866667"/>
    </inertial>
  </link>
  <joint name="allegro_hand_oya_finger_joint_13" type="revolute">
    <axis xyz="0 0 1"/>
    <limit effort="10" lower="-0.10499999999999998" upper="1.1629999999999998" velocity="0.5"/>
    <parent link="allegro_hand_oya_finger_link_12"/>
    <child link="allegro_hand_oya_finger_link_13"/>
    <origin xyz="-0.027 0.005 0.0399"/>
  </joint>
  <link name="allegro_hand_oya_finger_link_14">
    <visual>
      <geometry>
        <mesh filename="mesh/allegro/thumb_1.0.stl"/>
      </geometry>
      <material name="black"/>
    </visual>
    <collision>
      <geometry>
        <box size="0.0196 0.0275 0.0414"/>
      </geometry>
      <origin rpy="0 0 0" xyz="0 0 0.0257"/>
    </collision>
    <!--covers are always with sensors-->
    <inertial>
      <mass value="0.0457"/>
      <origin rpy="0 0 0" xyz="0 0 0"/>
      <inertia ixx="4.30439933333e-05" ixy="9.57068e-06" ixz="5.1205e-06" iyy="0.0010144451933333" iyz="1.342825e-05" izz="4.30439933333e-05"/>
    </inertial>
  </link>

  <joint name="allegro_hand_oya_finger_joint_14" type="revolute">
    <axis xyz="0 1 0"/>
    <limit effort="10" lower="-0.18899999999999997" upper="1.644" velocity="0.5"/>
    <parent link="allegro_hand_oya_finger_link_13"/>
    <child link="allegro_hand_oya_finger_link_14"/>
    <origin xyz="0 0 0.0177"/>
  </joint>
  <link name="allegro_hand_oya_finger_link_15">
    <visual>
      <geometry>
        <mesh filename="mesh/allegro/thumb_2.0.stl"/>
      </geometry>
      <material name="black"/>
    </visual>
    <collision>
      <geometry>
        <box size="0.0196 0.0275 0.042300000000000004"/>
      </geometry>
      <origin rpy="0 0 0" xyz="0 0 0.021150000000000002"/>
    </collision>
    <inertial>
      <mass value="0.0753"/>
      <origin rpy="0 0 0" xyz="0 0 0"/>
      <inertia ixx="2.90e-05" ixy="0.0" ixz="0.0" iyy="0.001000968" iyz="0.0" izz="6.88e-06"/>
    </inertial>
  </link>
  <joint name="allegro_hand_oya_finger_joint_15" type="revolute">
    <axis xyz="0 1 0"/>
    <limit effort="10" lower="-0.162" upper="1.7189999999999999" velocity="0.5"/>
    <parent link="allegro_hand_oya_finger_link_14"/>
    <child link="allegro_hand_oya_finger_link_15"/>
    <origin xyz="0 0 0.0514"/>
  </joint>
  <joint name="allegro_hand_oya_finger_3_aftc_fixed" type="fixed">
    <origin rpy="1.5707963267948966 0.0 1.5707963267948966" xyz="-0.013 0.0 0.0315"/>
    <parent link="allegro_hand_oya_finger_link_15"/>
    <child link="allegro_hand_oya_finger_3_aftc_base_link"/>
  </joint>
  <link name="allegro_hand_oya_finger_3_aftc_base_link">
    <collision>
      <origin rpy="0 0 0" xyz="0 0 0"/>
      <geometry>
        <mesh filename="mesh/ft_c.stl"/>
      </geometry>
    </collision>
    <visual>
      <origin rpy="0 0 0" xyz="0 0 0"/>
      <geometry>
        <mesh filename="mesh/ft_c.stl"/>
      </geometry>
      <material name="black"/>
    </visual>
    <inertial>
      <!-- <friction value="1.0"/> -->
      <mass value="0.0404"/>
      <origin rpy="0 0 0" xyz="0 0 0"/>
    </inertial>
  </link>
  <joint name="allegro_hand_oya_tip_fixed" type="fixed">
    <origin rpy="0 0.0 0" xyz="0 0.03 0"/>
    <parent link="allegro_hand_oya_finger_3_aftc_base_link"/>
    <child link="oya_ee"/>
  </joint>
  <link name="oya_ee">
    <inertial>
        <mass value="0.0001"/>
        <origin rpy="0 0 0" xyz="0 0 0"/>
        <inertia ixx="1e-07" ixy="0.0" ixz="0.0" iyy="1e-07" iyz="0.0" izz="1e-07"/>
    </inertial>
  </link>















  <gazebo reference="victor_pedestal">
    <visual>
      <material>
        <diffuse>0.2 0.2 0.2 1.0</diffuse>
        <ambient>0.1 0.1 0.1 1.0</ambient>
      </material>
    </visual>
  </gazebo>
  <gazebo reference="victor_base_plate">
    <visual>
      <material>
        <diffuse>0.7 0.7 0.7 1.0</diffuse>
        <ambient>0.3 0.3 0.3 1.0</ambient>
        <specular>0.9 0.9 0.9 1.0</specular>
      </material>
    </visual>
  </gazebo>
  <gazebo reference="right_tool_joint">
    <preserveFixedJoint>true</preserveFixedJoint>
  </gazebo>
  <gazebo reference="left_tool_joint">
    <preserveFixedJoint>true</preserveFixedJoint>
  </gazebo>
</robot>
